Workbook

Sheet DCF
B1: Moderna (MRNA) - DCF valuation
B2: ="Scenario: "&Inputs!$D$6&" | WACC "&TEXT(Inputs!$C$28,"0.0%")&" | terminal growth "&TEXT(Inputs!$F$48,"0.0%") -> Scenario: Base | WACC 11.7% | terminal growth 2.5%
A3: Valuation summary (US$ mm)
B4: Sum of PV of free cash flows, 2027-2040 | C4: =SUM(Model!$D$45:$Q$45) -> 6511.4032
B5: Terminal-year FCF x (1 + g) | C5: =Model!$Q$40*(1+Inputs!$F$48) -> 3125.9765
B6: Terminal value at end-2040 | C6: =C5/(Inputs!$C$28-Inputs!$F$48) -> 33819.452
B7: Discount period to end-2040 (years) | C7: =(DATE(Model!$Q$4,12,31)-Inputs!$C$9)/365 -> 14.249315
B8: PV of terminal value | C8: =C6/(1+Inputs!$C$28)^C7 -> 6951.0858
B9: Enterprise value | C9: =C4+C8 -> 13462.489
B10: plus: net cash (YE2026E cash less debt) | C10: =Inputs!$C$14 -> 4350
B11: Equity value | C11: =C9+C10 -> 17812.489
B12: Diluted shares (mm) | C12: =Inputs!$C$11 -> 396.82122
B13: Implied value per share (US$) | C13: =C11/C12 -> 44.887945
B14: Current share price (US$) | C14: =Inputs!$C$10 -> 190.01
B15: Upside / (downside) | C15: =C13/C14-1 -> -0.76376009
A17: Diagnostics
B18: Terminal value as % of enterprise value | C18: =IF(C9=0,0,C8/C9) -> 0.51632992
B19: Implied EV / 2040E revenue | C19: =IF(Model!$Q$13=0,0,C9/Model!$Q$13) -> 1.2686197
B20: 2040E revenue ($mm) | C20: =Model!$Q$13 -> 10611.919
B21: 2040E risk-adjusted intismeran revenue ($mm) | C21: =Model!$Q$12 -> 6775
B22: 2040E EBIT margin | C22: =Model!$Q$25 -> 0.36768251
B23: Market cap at current price ($mm) | C23: =Inputs!$C$15 -> 75400
B24: Market-implied enterprise value ($mm) | C24: =C23-Inputs!$C$14 -> 71050
A27: Sensitivity - implied value per share (US$): WACC (rows) vs terminal growth (columns)
B28: WACC step / growth step | C28: 0.01 | D28: 0.005
B29: WACC \ g | C29: =Inputs!$F$48+(0-2)*$D$28 -> 0.015 | D29: =Inputs!$F$48+(1-2)*$D$28 -> 0.02 | E29: =Inputs!$F$48+(2-2)*$D$28 -> 0.025 | F29: =Inputs!$F$48+(3-2)*$D$28 -> 0.03 | G29: =Inputs!$F$48+(4-2)*$D$28 -> 0.035
B30: =Inputs!$C$28+(0-3)*$C$28 -> 0.087431316 | C30: =(SUMPRODUCT(Model!$D$40:$Q$40,1/(1+$B30)^Model!$D$43:$Q$43)+Model!$Q$40*(1+C$29)/($B30-C$29)/(1+$B30)^$C$7+Inputs!$C$14)/Inputs!$C$11 -> 66.538305 | D30: =(SUMPRODUCT(Model!$D$40:$Q$40,1/(1+$B30)^Model!$D$43:$Q$43)+Model!$Q$40*(1+D$29)/($B30-D$29)/(1+$B30)^$C$7+Inputs!$C$14)/Inputs!$C$11 -> 69.129795 | E30: =(SUMPRODUCT(Model!$D$40:$Q$40,1/(1+$B30)^Model!$D$43:$Q$43)+Model!$Q$40*(1+E$29)/($B30-E$29)/(1+$B30)^$C$7+Inputs!$C$14)/Inputs!$C$11 -> 72.13638 | F30: =(SUMPRODUCT(Model!$D$40:$Q$40,1/(1+$B30)^Model!$D$43:$Q$43)+Model!$Q$40*(1+F$29)/($B30-F$29)/(1+$B30)^$C$7+Inputs!$C$14)/Inputs!$C$11 -> 75.666474 | G30: =(SUMPRODUCT(Model!$D$40:$Q$40,1/(1+$B30)^Model!$D$43:$Q$43)+Model!$Q$40*(1+G$29)/($B30-G$29)/(1+$B30)^$C$7+Inputs!$C$14)/Inputs!$C$11 -> 79.869848
B31: =Inputs!$C$28+(1-3)*$C$28 -> 0.097431316 | C31: =(SUMPRODUCT(Model!$D$40:$Q$40,1/(1+$B31)^Model!$D$43:$Q$43)+Model!$Q$40*(1+C$29)/($B31-C$29)/(1+$B31)^$C$7+Inputs!$C$14)/Inputs!$C$11 -> 56.66872 | D31: =(SUMPRODUCT(Model!$D$40:$Q$40,1/(1+$B31)^Model!$D$43:$Q$43)+Model!$Q$40*(1+D$29)/($B31-D$29)/(1+$B31)^$C$7+Inputs!$C$14)/Inputs!$C$11 -> 58.425252 | E31: =(SUMPRODUCT(Model!$D$40:$Q$40,1/(1+$B31)^Model!$D$43:$Q$43)+Model!$Q$40*(1+E$29)/($B31-E$29)/(1+$B31)^$C$7+Inputs!$C$14)/Inputs!$C$11 -> 60.424293 | F31: =(SUMPRODUCT(Model!$D$40:$Q$40,1/(1+$B31)^Model!$D$43:$Q$43)+Model!$Q$40*(1+F$29)/($B31-F$29)/(1+$B31)^$C$7+Inputs!$C$14)/Inputs!$C$11 -> 62.71979 | G31: =(SUMPRODUCT(Model!$D$40:$Q$40,1/(1+$B31)^Model!$D$43:$Q$43)+Model!$Q$40*(1+G$29)/($B31-G$29)/(1+$B31)^$C$7+Inputs!$C$14)/Inputs!$C$11 -> 65.38297
B32: =Inputs!$C$28+(2-3)*$C$28 -> 0.10743132 | C32: =(SUMPRODUCT(Model!$D$40:$Q$40,1/(1+$B32)^Model!$D$43:$Q$43)+Model!$Q$40*(1+C$29)/($B32-C$29)/(1+$B32)^$C$7+Inputs!$C$14)/Inputs!$C$11 -> 49.052797 | D32: =(SUMPRODUCT(Model!$D$40:$Q$40,1/(1+$B32)^Model!$D$43:$Q$43)+Model!$Q$40*(1+D$29)/($B32-D$29)/(1+$B32)^$C$7+Inputs!$C$14)/Inputs!$C$11 -> 50.28302 | E32: =(SUMPRODUCT(Model!$D$40:$Q$40,1/(1+$B32)^Model!$D$43:$Q$43)+Model!$Q$40*(1+E$29)/($B32-E$29)/(1+$B32)^$C$7+Inputs!$C$14)/Inputs!$C$11 -> 51.662484 | F32: =(SUMPRODUCT(Model!$D$40:$Q$40,1/(1+$B32)^Model!$D$43:$Q$43)+Model!$Q$40*(1+F$29)/($B32-F$29)/(1+$B32)^$C$7+Inputs!$C$14)/Inputs!$C$11 -> 53.220101 | G32: =(SUMPRODUCT(Model!$D$40:$Q$40,1/(1+$B32)^Model!$D$43:$Q$43)+Model!$Q$40*(1+G$29)/($B32-G$29)/(1+$B32)^$C$7+Inputs!$C$14)/Inputs!$C$11 -> 54.992766
B33: =Inputs!$C$28+(3-3)*$C$28 -> 0.11743132 | C33: =(SUMPRODUCT(Model!$D$40:$Q$40,1/(1+$B33)^Model!$D$43:$Q$43)+Model!$Q$40*(1+C$29)/($B33-C$29)/(1+$B33)^$C$7+Inputs!$C$14)/Inputs!$C$11 -> 43.023618 | D33: =(SUMPRODUCT(Model!$D$40:$Q$40,1/(1+$B33)^Model!$D$43:$Q$43)+Model!$Q$40*(1+D$29)/($B33-D$29)/(1+$B33)^$C$7+Inputs!$C$14)/Inputs!$C$11 -> 43.907945 | E33: =(SUMPRODUCT(Model!$D$40:$Q$40,1/(1+$B33)^Model!$D$43:$Q$43)+Model!$Q$40*(1+E$29)/($B33-E$29)/(1+$B33)^$C$7+Inputs!$C$14)/Inputs!$C$11 -> 44.887945 | F33: =(SUMPRODUCT(Model!$D$40:$Q$40,1/(1+$B33)^Model!$D$43:$Q$43)+Model!$Q$40*(1+F$29)/($B33-F$29)/(1+$B33)^$C$7+Inputs!$C$14)/Inputs!$C$11 -> 45.980033 | G33: =(SUMPRODUCT(Model!$D$40:$Q$40,1/(1+$B33)^Model!$D$43:$Q$43)+Model!$Q$40*(1+G$29)/($B33-G$29)/(1+$B33)^$C$7+Inputs!$C$14)/Inputs!$C$11 -> 47.204606
B34: =Inputs!$C$28+(4-3)*$C$28 -> 0.12743132 | C34: =(SUMPRODUCT(Model!$D$40:$Q$40,1/(1+$B34)^Model!$D$43:$Q$43)+Model!$Q$40*(1+C$29)/($B34-C$29)/(1+$B34)^$C$7+Inputs!$C$14)/Inputs!$C$11 -> 38.152184 | D34: =(SUMPRODUCT(Model!$D$40:$Q$40,1/(1+$B34)^Model!$D$43:$Q$43)+Model!$Q$40*(1+D$29)/($B34-D$29)/(1+$B34)^$C$7+Inputs!$C$14)/Inputs!$C$11 -> 38.801506 | E34: =(SUMPRODUCT(Model!$D$40:$Q$40,1/(1+$B34)^Model!$D$43:$Q$43)+Model!$Q$40*(1+E$29)/($B34-E$29)/(1+$B34)^$C$7+Inputs!$C$14)/Inputs!$C$11 -> 39.51422 | F34: =(SUMPRODUCT(Model!$D$40:$Q$40,1/(1+$B34)^Model!$D$43:$Q$43)+Model!$Q$40*(1+F$29)/($B34-F$29)/(1+$B34)^$C$7+Inputs!$C$14)/Inputs!$C$11 -> 40.300085 | G34: =(SUMPRODUCT(Model!$D$40:$Q$40,1/(1+$B34)^Model!$D$43:$Q$43)+Model!$Q$40*(1+G$29)/($B34-G$29)/(1+$B34)^$C$7+Inputs!$C$14)/Inputs!$C$11 -> 41.17097
B35: =Inputs!$C$28+(5-3)*$C$28 -> 0.13743132 | C35: =(SUMPRODUCT(Model!$D$40:$Q$40,1/(1+$B35)^Model!$D$43:$Q$43)+Model!$Q$40*(1+C$29)/($B35-C$29)/(1+$B35)^$C$7+Inputs!$C$14)/Inputs!$C$11 -> 34.150158 | D35: =(SUMPRODUCT(Model!$D$40:$Q$40,1/(1+$B35)^Model!$D$43:$Q$43)+Model!$Q$40*(1+D$29)/($B35-D$29)/(1+$B35)^$C$7+Inputs!$C$14)/Inputs!$C$11 -> 34.635435 | E35: =(SUMPRODUCT(Model!$D$40:$Q$40,1/(1+$B35)^Model!$D$43:$Q$43)+Model!$Q$40*(1+E$29)/($B35-E$29)/(1+$B35)^$C$7+Inputs!$C$14)/Inputs!$C$11 -> 35.163875 | F35: =(SUMPRODUCT(Model!$D$40:$Q$40,1/(1+$B35)^Model!$D$43:$Q$43)+Model!$Q$40*(1+F$29)/($B35-F$29)/(1+$B35)^$C$7+Inputs!$C$14)/Inputs!$C$11 -> 35.741503 | G35: =(SUMPRODUCT(Model!$D$40:$Q$40,1/(1+$B35)^Model!$D$43:$Q$43)+Model!$Q$40*(1+G$29)/($B35-G$29)/(1+$B35)^$C$7+Inputs!$C$14)/Inputs!$C$11 -> 36.375523
B36: =Inputs!$C$28+(6-3)*$C$28 -> 0.14743132 | C36: =(SUMPRODUCT(Model!$D$40:$Q$40,1/(1+$B36)^Model!$D$43:$Q$43)+Model!$Q$40*(1+C$29)/($B36-C$29)/(1+$B36)^$C$7+Inputs!$C$14)/Inputs!$C$11 -> 30.816695 | D36: =(SUMPRODUCT(Model!$D$40:$Q$40,1/(1+$B36)^Model!$D$43:$Q$43)+Model!$Q$40*(1+D$29)/($B36-D$29)/(1+$B36)^$C$7+Inputs!$C$14)/Inputs!$C$11 -> 31.184851 | E36: =(SUMPRODUCT(Model!$D$40:$Q$40,1/(1+$B36)^Model!$D$43:$Q$43)+Model!$Q$40*(1+E$29)/($B36-E$29)/(1+$B36)^$C$7+Inputs!$C$14)/Inputs!$C$11 -> 31.583078 | F36: =(SUMPRODUCT(Model!$D$40:$Q$40,1/(1+$B36)^Model!$D$43:$Q$43)+Model!$Q$40*(1+F$29)/($B36-F$29)/(1+$B36)^$C$7+Inputs!$C$14)/Inputs!$C$11 -> 32.015216 | G36: =(SUMPRODUCT(Model!$D$40:$Q$40,1/(1+$B36)^Model!$D$43:$Q$43)+Model!$Q$40*(1+G$29)/($B36-G$29)/(1+$B36)^$C$7+Inputs!$C$14)/Inputs!$C$11 -> 32.48579
B38: Centre cell matches the live valuation above. Rows and columns are re-centred on the live WACC and growth rate.

Sheet Inputs
B1: Moderna (MRNA) DCF - Inputs
B2: US$ millions unless stated. Blue = hard-coded input, black = formula, green = link from another sheet. Yellow = key lever. Hover over cells with a red corner for sources.
B4: Scenario selector
B6: Active scenario (1 = Bear, 2 = Base, 3 = Bull) | C6: 2 | D6: =CHOOSE(C6,"Bear","Base","Bull") -> Base
A8: Market data & balance sheet
B9: Valuation date | C9: 46300 | G9: Model date.
B10: Share price (US$) | C10: 190.01 | G10: Closing price Oct 2 2026 and market cap US$75.4bn: https://www.ad-hoc-news.de/boerse/news/corporate-news/moderna-stock-gained-0-57-percent-as-nasdaq-100-entry-nears/70226496
B11: Diluted shares outstanding (mm) | C11: =75400/C10 -> 396.82122 | G11: Market cap US$75.4bn / price US$190.01. Closing price Oct 2 2026 and market cap US$75.4bn: https://www.ad-hoc-news.de/boerse/news/corporate-news/moderna-stock-gained-0-57-percent-as-nasdaq-100-entry-nears/70226496
B12: Cash & investments, YE2026E ($mm) | C12: 4950 | G12: Midpoint of US$4.7-5.2bn year-end 2026 guidance (already net of the $950mm July 2026 settlement and remaining 2026 burn). Moderna Q2 2026 press release (8-K Ex. 99.1, Jul 31 2026): https://www.sec.gov/Archives/edgar/data/0001682852/000168285226000147/exhibit9912026q2pressrelea.htm
B13: Debt ($mm) | C13: 600 | G13: US$0.6bn drawn on the US$1.5bn Ares term loan; balance sheet long-term debt US$591mm at Jun 30 2026. Moderna JPM 2026 update (8-K Ex. 99.1, Jan 12 2026): https://www.sec.gov/Archives/edgar/data/1682852/000168285226000007/exhibit991-01122026.htm
B14: Net cash ($mm) | C14: =C12-C13 -> 4350
B15: Market capitalization ($mm) | C15: =C10*C11 -> 75400
A17: Discount rate (WACC)
B18: Risk-free rate (10-yr UST) | C18: 0.0528 | G18: 10-yr Treasury par yield 5.28% (Oct 2 2026): https://stockmarketwatch.com/bonds/10-year-treasury-yield
B19: Equity beta | C19: 1.3 | G19: Assumption; MRNA's historical beta has ranged ~1.2-1.8.
B20: Equity risk premium | C20: 0.05 | G20: Assumption (Damodaran-style implied ERP ~4.5-5.5%).
B21: Pre-tax cost of debt | C21: 0.09 | G21: Approx. rate on Ares term loan; assumption.
B22: Cost of equity (CAPM) | C22: =C18+C19*C20 -> 0.1178
B23: After-tax cost of debt | C23: =C21*(1-$C$66) -> 0.0711
B24: Equity weight | C24: =$C$15/($C$15+$C$13) -> 0.99210526
B25: Debt weight | C25: =1-C24 -> 0.0078947368
B26: WACC (calculated) | C26: =C24*C22+C25*C23 -> 0.11743132
B27: WACC override (leave blank to use calculated)
B28: WACC used | C28: =IF(ISNUMBER(C27),C27,C26) -> 0.11743132
A30: Scenario levers
B31: Lever | C31: Bear | D31: Base | E31: Bull | F31: Live | G31: Rationale / source
B32: Respiratory vaccines
B33: Vaccine revenue growth 2027-2030 | C33: 0.02 | D33: 0.08 | E33: 0.15 | F33: =CHOOSE($C$6,C33,D33,E33) -> 0.08 | G33: Flu (mFLUSIVA), flu+COVID (mCOMBRIAX), norovirus launches drive growth; company targets up to 10% growth in 2026.
B34: Vaccine revenue growth 2031-2035 | C34: 0 | D34: 0.04 | E34: 0.06 | F34: =CHOOSE($C$6,C34,D34,E34) -> 0.04 | G34: Assumption.
B35: Vaccine revenue growth 2036-2040 | C35: -0.02 | D35: 0.02 | E35: 0.03 | F35: =CHOOSE($C$6,C35,D35,E35) -> 0.02 | G35: Assumption.
B36: Vaccine gross margin, steady state (from 2030) | C36: 0.55 | D36: 0.65 | E36: 0.72 | F36: =CHOOSE($C$6,C36,D36,E36) -> 0.65 | G36: 2026E ~62% (guided ~$0.8bn cost of sales ex. $0.9bn settlement on ~$2.1bn revenue); management expects manufacturing improvements to lift margins.
B37: Intismeran - adjuvant melanoma
B38: Peak revenue to Moderna ($mm) | C38: 2500 | D38: 4000 | E38: 5500 | F38: =CHOOSE($C$6,C38,D38,E38) -> 4000 | G38: Moderna's half of the Merck 50/50 profit share. William Blair models >$5.4bn to Moderna by 2040.
B39: Probability of approval | C39: 0.8 | D39: 0.9 | E39: 0.95 | F39: =CHOOSE($C$6,C39,D39,E39) -> 0.9 | G39: Phase 3 INTerpath-001 met RFS primary endpoint (Aug 19 2026).
B40: Intismeran - NSCLC
B41: Peak revenue to Moderna ($mm) | C41: 2000 | D41: 5000 | E41: 10000 | F41: =CHOOSE($C$6,C41,D41,E41) -> 5000 | G41: William Blair models ~$10bn to Moderna by 2040 (bull case).
B42: Probability of approval | C42: 0.35 | D42: 0.5 | E42: 0.6 | F42: =CHOOSE($C$6,C42,D42,E42) -> 0.5 | G42: Phase 3 ongoing; assumption.
B43: Intismeran - RCC, bladder & other
B44: Peak revenue to Moderna ($mm) | C44: 500 | D44: 1500 | E44: 3300 | F44: =CHOOSE($C$6,C44,D44,E44) -> 1500 | G44: William Blair models ~$3.3bn RCC to Moderna by 2040 (bull case).
B45: Probability of approval | C45: 0.3 | D45: 0.45 | E45: 0.55 | F45: =CHOOSE($C$6,C45,D45,E45) -> 0.45 | G45: Phase 2/3 ongoing; assumption.
...

Sheet Model
A1: Moderna (MRNA) - Operating model & free cash flow (US$ mm)
A2: ="Scenario: "&Inputs!$D$6 -> Scenario: Base
A4: Fiscal year (Dec) | B4: 2025 | C4: 2026 | D4: =C4+1 -> 2027 | E4: =D4+1 -> 2028 | F4: =E4+1 -> 2029 | G4: =F4+1 -> 2030 | H4: =G4+1 -> 2031 | I4: =H4+1 -> 2032 | J4: =I4+1 -> 2033 | K4: =J4+1 -> 2034 | ... Q4: =P4+1 -> 2040
B5: Actual | C5: Guide | D5: Forecast | E5: Forecast | F5: Forecast | G5: Forecast | H5: Forecast | I5: Forecast | J5: Forecast | K5: Forecast | L5: Forecast | M5: Forecast | N5: Forecast | O5: Forecast | P5: Forecast | Q5: Forecast
A7: Revenue
A8: Respiratory vaccines (COVID, RSV, flu, combo, noro) | B8: 1944 | C8: =B8*1.08 -> 2099.52 | D8: =C8*(1+IF(D$4<=2030,Inputs!$F$33,IF(D$4<=2035,Inputs!$F$34,Inputs!$F$35))) -> 2267.4816 | E8: =D8*(1+IF(E$4<=2030,Inputs!$F$33,IF(E$4<=2035,Inputs!$F$34,Inputs!$F$35))) -> 2448.8801 | F8: =E8*(1+IF(F$4<=2030,Inputs!$F$33,IF(F$4<=2035,Inputs!$F$34,Inputs!$F$35))) -> 2644.7905 | G8: =F8*(1+IF(G$4<=2030,Inputs!$F$33,IF(G$4<=2035,Inputs!$F$34,Inputs!$F$35))) -> 2856.3738 | H8: =G8*(1+IF(H$4<=2030,Inputs!$F$33,IF(H$4<=2035,Inputs!$F$34,Inputs!$F$35))) -> 2970.6287 | I8: =H8*(1+IF(I$4<=2030,Inputs!$F$33,IF(I$4<=2035,Inputs!$F$34,Inputs!$F$35))) -> 3089.4539 | J8: =I8*(1+IF(J$4<=2030,Inputs!$F$33,IF(J$4<=2035,Inputs!$F$34,Inputs!$F$35))) -> 3213.032 | K8: =J8*(1+IF(K$4<=2030,Inputs!$F$33,IF(K$4<=2035,Inputs!$F$34,Inputs!$F$35))) -> 3341.5533 | ... Q8: =P8*(1+IF(Q$4<=2030,Inputs!$F$33,IF(Q$4<=2035,Inputs!$F$34,Inputs!$F$35))) -> 3836.9187
A9: Intismeran - melanoma (risk-adjusted, Moderna share) | B9: 0 | C9: 0 | D9: =IF(D$4>=Inputs!$C$54,MIN(1,(D$4-Inputs!$C$54+1)/Inputs!$C$57),0)*Inputs!$F$38*Inputs!$F$39 -> 0 | E9: =IF(E$4>=Inputs!$C$54,MIN(1,(E$4-Inputs!$C$54+1)/Inputs!$C$57),0)*Inputs!$F$38*Inputs!$F$39 -> 600 | F9: =IF(F$4>=Inputs!$C$54,MIN(1,(F$4-Inputs!$C$54+1)/Inputs!$C$57),0)*Inputs!$F$38*Inputs!$F$39 -> 1200 | G9: =IF(G$4>=Inputs!$C$54,MIN(1,(G$4-Inputs!$C$54+1)/Inputs!$C$57),0)*Inputs!$F$38*Inputs!$F$39 -> 1800 | H9: =IF(H$4>=Inputs!$C$54,MIN(1,(H$4-Inputs!$C$54+1)/Inputs!$C$57),0)*Inputs!$F$38*Inputs!$F$39 -> 2400 | I9: =IF(I$4>=Inputs!$C$54,MIN(1,(I$4-Inputs!$C$54+1)/Inputs!$C$57),0)*Inputs!$F$38*Inputs!$F$39 -> 3000 | J9: =IF(J$4>=Inputs!$C$54,MIN(1,(J$4-Inputs!$C$54+1)/Inputs!$C$57),0)*Inputs!$F$38*Inputs!$F$39 -> 3600 | K9: =IF(K$4>=Inputs!$C$54,MIN(1,(K$4-Inputs!$C$54+1)/Inputs!$C$57),0)*Inputs!$F$38*Inputs!$F$39 -> 3600 | ... Q9: =IF(Q$4>=Inputs!$C$54,MIN(1,(Q$4-Inputs!$C$54+1)/Inputs!$C$57),0)*Inputs!$F$38*Inputs!$F$39 -> 3600
A10: Intismeran - NSCLC (risk-adjusted) | B10: 0 | C10: 0 | D10: =IF(D$4>=Inputs!$C$55,MIN(1,(D$4-Inputs!$C$55+1)/Inputs!$C$57),0)*Inputs!$F$41*Inputs!$F$42 -> 0 | E10: =IF(E$4>=Inputs!$C$55,MIN(1,(E$4-Inputs!$C$55+1)/Inputs!$C$57),0)*Inputs!$F$41*Inputs!$F$42 -> 0 | F10: =IF(F$4>=Inputs!$C$55,MIN(1,(F$4-Inputs!$C$55+1)/Inputs!$C$57),0)*Inputs!$F$41*Inputs!$F$42 -> 0 | G10: =IF(G$4>=Inputs!$C$55,MIN(1,(G$4-Inputs!$C$55+1)/Inputs!$C$57),0)*Inputs!$F$41*Inputs!$F$42 -> 416.66667 | H10: =IF(H$4>=Inputs!$C$55,MIN(1,(H$4-Inputs!$C$55+1)/Inputs!$C$57),0)*Inputs!$F$41*Inputs!$F$42 -> 833.33333 | I10: =IF(I$4>=Inputs!$C$55,MIN(1,(I$4-Inputs!$C$55+1)/Inputs!$C$57),0)*Inputs!$F$41*Inputs!$F$42 -> 1250 | J10: =IF(J$4>=Inputs!$C$55,MIN(1,(J$4-Inputs!$C$55+1)/Inputs!$C$57),0)*Inputs!$F$41*Inputs!$F$42 -> 1666.6667 | K10: =IF(K$4>=Inputs!$C$55,MIN(1,(K$4-Inputs!$C$55+1)/Inputs!$C$57),0)*Inputs!$F$41*Inputs!$F$42 -> 2083.3333 | ... Q10: =IF(Q$4>=Inputs!$C$55,MIN(1,(Q$4-Inputs!$C$55+1)/Inputs!$C$57),0)*Inputs!$F$41*Inputs!$F$42 -> 2500
A11: Intismeran - RCC, bladder & other (risk-adjusted) | B11: 0 | C11: 0 | D11: =IF(D$4>=Inputs!$C$56,MIN(1,(D$4-Inputs!$C$56+1)/Inputs!$C$57),0)*Inputs!$F$44*Inputs!$F$45 -> 0 | E11: =IF(E$4>=Inputs!$C$56,MIN(1,(E$4-Inputs!$C$56+1)/Inputs!$C$57),0)*Inputs!$F$44*Inputs!$F$45 -> 0 | F11: =IF(F$4>=Inputs!$C$56,MIN(1,(F$4-Inputs!$C$56+1)/Inputs!$C$57),0)*Inputs!$F$44*Inputs!$F$45 -> 0 | G11: =IF(G$4>=Inputs!$C$56,MIN(1,(G$4-Inputs!$C$56+1)/Inputs!$C$57),0)*Inputs!$F$44*Inputs!$F$45 -> 112.5 | H11: =IF(H$4>=Inputs!$C$56,MIN(1,(H$4-Inputs!$C$56+1)/Inputs!$C$57),0)*Inputs!$F$44*Inputs!$F$45 -> 225 | I11: =IF(I$4>=Inputs!$C$56,MIN(1,(I$4-Inputs!$C$56+1)/Inputs!$C$57),0)*Inputs!$F$44*Inputs!$F$45 -> 337.5 | J11: =IF(J$4>=Inputs!$C$56,MIN(1,(J$4-Inputs!$C$56+1)/Inputs!$C$57),0)*Inputs!$F$44*Inputs!$F$45 -> 450 | K11: =IF(K$4>=Inputs!$C$56,MIN(1,(K$4-Inputs!$C$56+1)/Inputs!$C$57),0)*Inputs!$F$44*Inputs!$F$45 -> 562.5 | ... Q11: =IF(Q$4>=Inputs!$C$56,MIN(1,(Q$4-Inputs!$C$56+1)/Inputs!$C$57),0)*Inputs!$F$44*Inputs!$F$45 -> 675
A12: Total intismeran | B12: =SUM(B9:B11) -> 0 | C12: =SUM(C9:C11) -> 0 | D12: =SUM(D9:D11) -> 0 | E12: =SUM(E9:E11) -> 600 | F12: =SUM(F9:F11) -> 1200 | G12: =SUM(G9:G11) -> 2329.1667 | H12: =SUM(H9:H11) -> 3458.3333 | I12: =SUM(I9:I11) -> 4587.5 | ... Q12: =SUM(Q9:Q11) -> 6775
A13: Total revenue | B13: =B8+B12 -> 1944 | C13: =C8+C12 -> 2099.52 | D13: =D8+D12 -> 2267.4816 | E13: =E8+E12 -> 3048.8801 | F13: =F8+F12 -> 3844.7905 | G13: =G8+G12 -> 5185.5404 | H13: =H8+H12 -> 6428.9621 | I13: =I8+I12 -> 7676.9539 | ... Q13: =Q8+Q12 -> 10611.919
A14: growth % | C14: =IF(B13=0,0,C13/B13-1) -> 0.08 | D14: =IF(C13=0,0,D13/C13-1) -> 0.08 | E14: =IF(D13=0,0,E13/D13-1) -> 0.34461075 | F14: =IF(E13=0,0,F13/E13-1) -> 0.26105008 | G14: =IF(F13=0,0,G13/F13-1) -> 0.34871858 | H14: =IF(G13=0,0,H13/G13-1) -> 0.23978631 | I14: =IF(H13=0,0,I13/H13-1) -> 0.19412026 | J14: =IF(I13=0,0,J13/I13-1) -> 0.16318254 | ... Q14: =IF(P13=0,0,Q13/P13-1) -> 0.0071401679
A16: Operating costs
A17: Vaccine gross margin % | C17: =Inputs!$C$58 -> 0.62 | D17: =IF(D$4>=2030,Inputs!$F$36,Inputs!$C$58+(Inputs!$F$36-Inputs!$C$58)*(D$4-2026)/4) -> 0.6275 | E17: =IF(E$4>=2030,Inputs!$F$36,Inputs!$C$58+(Inputs!$F$36-Inputs!$C$58)*(E$4-2026)/4) -> 0.635 | F17: =IF(F$4>=2030,Inputs!$F$36,Inputs!$C$58+(Inputs!$F$36-Inputs!$C$58)*(F$4-2026)/4) -> 0.6425 | G17: =IF(G$4>=2030,Inputs!$F$36,Inputs!$C$58+(Inputs!$F$36-Inputs!$C$58)*(G$4-2026)/4) -> 0.65 | H17: =IF(H$4>=2030,Inputs!$F$36,Inputs!$C$58+(Inputs!$F$36-Inputs!$C$58)*(H$4-2026)/4) -> 0.65 | I17: =IF(I$4>=2030,Inputs!$F$36,Inputs!$C$58+(Inputs!$F$36-Inputs!$C$58)*(I$4-2026)/4) -> 0.65 | J17: =IF(J$4>=2030,Inputs!$F$36,Inputs!$C$58+(Inputs!$F$36-Inputs!$C$58)*(J$4-2026)/4) -> 0.65 | K17: =IF(K$4>=2030,Inputs!$F$36,Inputs!$C$58+(Inputs!$F$36-Inputs!$C$58)*(K$4-2026)/4) -> 0.65 | ... Q17: =IF(Q$4>=2030,Inputs!$F$36,Inputs!$C$58+(Inputs!$F$36-Inputs!$C$58)*(Q$4-2026)/4) -> 0.65
A18: Cost of sales - vaccines | C18: =C8*(1-C17) -> 797.8176 | D18: =D8*(1-D17) -> 844.6369 | E18: =E8*(1-E17) -> 893.84125 | F18: =F8*(1-F17) -> 945.51262 | G18: =G8*(1-G17) -> 999.73082 | H18: =H8*(1-H17) -> 1039.7201 | I18: =I8*(1-I17) -> 1081.3089 | J18: =J8*(1-J17) -> 1124.5612 | ... Q18: =Q8*(1-Q17) -> 1342.9215
A19: Cost of sales - intismeran | C19: =C12*Inputs!$F$47 -> 0 | D19: =D12*Inputs!$F$47 -> 0 | E19: =E12*Inputs!$F$47 -> 150 | F19: =F12*Inputs!$F$47 -> 300 | G19: =G12*Inputs!$F$47 -> 582.29167 | H19: =H12*Inputs!$F$47 -> 864.58333 | I19: =I12*Inputs!$F$47 -> 1146.875 | J19: =J12*Inputs!$F$47 -> 1429.1667 | ... Q19: =Q12*Inputs!$F$47 -> 1693.75
A20: Gross profit | C20: =C13-C18-C19 -> 1301.7024 | D20: =D13-D18-D19 -> 1422.8447 | E20: =E13-E18-E19 -> 2005.0389 | F20: =F13-F18-F19 -> 2599.2779 | G20: =G13-G18-G19 -> 3603.518 | H20: =H13-H18-H19 -> 4524.6587 | I20: =I13-I18-I19 -> 5448.77 | J20: =J13-J18-J19 -> 6375.9708 | ... Q20: =Q13-Q18-Q19 -> 7575.2471
A21: gross margin % | C21: =IF(C13=0,0,C20/C13) -> 0.62 | D21: =IF(D13=0,0,D20/D13) -> 0.6275 | E21: =IF(E13=0,0,E20/E13) -> 0.65763126 | F21: =IF(F13=0,0,F20/F13) -> 0.67605189 | G21: =IF(G13=0,0,G20/G13) -> 0.69491657 | H21: =IF(H13=0,0,H20/H13) -> 0.70379303 | I21: =IF(I13=0,0,I20/I13) -> 0.70975677 | J21: =IF(J13=0,0,J20/J13) -> 0.71401858 | ... Q21: =IF(Q13=0,0,Q20/Q13) -> 0.71384331
A22: Research & development | C22: 2900 | D22: 2400 | E22: =MAX(Inputs!$F$50,Inputs!$C$59*E13) -> 2400 | F22: =MAX(Inputs!$F$50,Inputs!$C$59*F13) -> 2400 | G22: =MAX(Inputs!$F$50,Inputs!$C$59*G13) -> 2400 | H22: =MAX(Inputs!$F$50,Inputs!$C$59*H13) -> 2400 | I22: =MAX(Inputs!$F$50,Inputs!$C$59*I13) -> 2400 | J22: =MAX(Inputs!$F$50,Inputs!$C$59*J13) -> 2400 | K22: =MAX(Inputs!$F$50,Inputs!$C$59*K13) -> 2400 | L22: =MAX(Inputs!$F$50,Inputs!$C$59*L13) -> 2400 | ... Q22: =MAX(Inputs!$F$50,Inputs!$C$59*Q13) -> 2400
A23: Selling, general & administrative | C23: 1000 | D23: 950 | E23: =MAX(Inputs!$F$51,Inputs!$C$60*E13) -> 900 | F23: =MAX(Inputs!$F$51,Inputs!$C$60*F13) -> 900 | G23: =MAX(Inputs!$F$51,Inputs!$C$60*G13) -> 900 | H23: =MAX(Inputs!$F$51,Inputs!$C$60*H13) -> 900 | I23: =MAX(Inputs!$F$51,Inputs!$C$60*I13) -> 921.23447 | J23: =MAX(Inputs!$F$51,Inputs!$C$60*J13) -> 1071.5638 | K23: =MAX(Inputs!$F$51,Inputs!$C$60*K13) -> 1150.4864 | L23: =MAX(Inputs!$F$51,Inputs!$C$60*L13) -> 1230.0259 | ... Q23: =MAX(Inputs!$F$51,Inputs!$C$60*Q13) -> 1273.4302
A24: Operating income (EBIT) | C24: =C20-C22-C23 -> -2598.2976 | D24: =D20-D22-D23 -> -1927.1553 | E24: =E20-E22-E23 -> -1294.9611 | F24: =F20-F22-F23 -> -700.72208 | G24: =G20-G22-G23 -> 303.51796 | H24: =H20-H22-H23 -> 1224.6587 | I24: =I20-I22-I23 -> 2127.5356 | J24: =J20-J22-J23 -> 2904.407 | ... Q24: =Q20-Q22-Q23 -> 3901.8169
A25: EBIT margin % | C25: =IF(C13=0,0,C24/C13) -> -1.2375674 | D25: =IF(D13=0,0,D24/D13) -> -0.84991 | E25: =IF(E13=0,0,E24/E13) -> -0.42473337 | F25: =IF(F13=0,0,F24/F13) -> -0.18225234 | G25: =IF(G13=0,0,G24/G13) -> 0.058531596 | H25: =IF(H13=0,0,H24/H13) -> 0.19049089 | I25: =IF(I13=0,0,I24/I13) -> 0.27713278 | J25: =IF(J13=0,0,J24/J13) -> 0.32525252 | ... Q25: =IF(Q13=0,0,Q24/Q13) -> 0.36768251
A27: Cash taxes (NOL shield)
A28: NOL balance - beginning | D28: =Inputs!$C$67 -> 12000 | E28: =D30 -> 12000 | F28: =E30 -> 12000 | G28: =F30 -> 12000 | H28: =G30 -> 11757.186 | I28: =H30 -> 10777.459 | J28: =I30 -> 9075.4302 | K28: =J30 -> 6751.9047 | L28: =K30 -> 4107.1861 | ... Q28: =P30 -> 0
A29: NOL utilized | D29: =MIN(D28,Inputs!$C$68*MAX(D24,0)) -> 0 | E29: =MIN(E28,Inputs!$C$68*MAX(E24,0)) -> 0 | F29: =MIN(F28,Inputs!$C$68*MAX(F24,0)) -> 0 | G29: =MIN(G28,Inputs!$C$68*MAX(G24,0)) -> 242.81437 | H29: =MIN(H28,Inputs!$C$68*MAX(H24,0)) -> 979.72694 | I29: =MIN(I28,Inputs!$C$68*MAX(I24,0)) -> 1702.0284 | J29: =MIN(J28,Inputs!$C$68*MAX(J24,0)) -> 2323.5256 | K29: =MIN(K28,Inputs!$C$68*MAX(K24,0)) -> 2644.7186 | ... Q29: =MIN(Q28,Inputs!$C$68*MAX(Q24,0)) -> 0
A30: NOL balance - ending | D30: =D28-D29 -> 12000 | E30: =E28-E29 -> 12000 | F30: =F28-F29 -> 12000 | G30: =G28-G29 -> 11757.186 | H30: =H28-H29 -> 10777.459 | I30: =I28-I29 -> 9075.4302 | J30: =J28-J29 -> 6751.9047 | K30: =K28-K29 -> 4107.1861 | ... Q30: =Q28-Q29 -> 0
A31: Taxable income | D31: =MAX(D24,0)-D29 -> 0 | E31: =MAX(E24,0)-E29 -> 0 | F31: =MAX(F24,0)-F29 -> 0 | G31: =MAX(G24,0)-G29 -> 60.703592 | H31: =MAX(H24,0)-H29 -> 244.93174 | I31: =MAX(I24,0)-I29 -> 425.50711 | J31: =MAX(J24,0)-J29 -> 580.8814 | K31: =MAX(K24,0)-K29 -> 661.17965 | ... Q31: =MAX(Q24,0)-Q29 -> 3901.8169
A32: Cash taxes | D32: =D31*Inputs!$C$66 -> 0 | E32: =E31*Inputs!$C$66 -> 0 | F32: =F31*Inputs!$C$66 -> 0 | G32: =G31*Inputs!$C$66 -> 12.747754 | H32: =H31*Inputs!$C$66 -> 51.435664 | I32: =I31*Inputs!$C$66 -> 89.356493 | J32: =J31*Inputs!$C$66 -> 121.98509 | K32: =K31*Inputs!$C$66 -> 138.84773 | ... Q32: =Q31*Inputs!$C$66 -> 819.38155
A34: Unlevered free cash flow
A35: EBIT | D35: =D24 -> -1927.1553 | E35: =E24 -> -1294.9611 | F35: =F24 -> -700.72208 | G35: =G24 -> 303.51796 | H35: =H24 -> 1224.6587 | I35: =I24 -> 2127.5356 | J35: =J24 -> 2904.407 | K35: =K24 -> 3305.8983 | ... Q35: =Q24 -> 3901.8169
A36: less: cash taxes | D36: =-D32 -> 0 | E36: =-E32 -> 0 | F36: =-F32 -> 0 | G36: =-G32 -> -12.747754 | H36: =-H32 -> -51.435664 | I36: =-I32 -> -89.356493 | J36: =-J32 -> -121.98509 | K36: =-K32 -> -138.84773 | ... Q36: =-Q32 -> -819.38155
A37: plus: D&A | D37: =MAX(Inputs!$C$61,Inputs!$C$62*D13) -> 350 | E37: =MAX(Inputs!$C$61,Inputs!$C$62*E13) -> 350 | F37: =MAX(Inputs!$C$61,Inputs!$C$62*F13) -> 350 | G37: =MAX(Inputs!$C$61,Inputs!$C$62*G13) -> 350 | H37: =MAX(Inputs!$C$61,Inputs!$C$62*H13) -> 350 | I37: =MAX(Inputs!$C$61,Inputs!$C$62*I13) -> 350 | J37: =MAX(Inputs!$C$61,Inputs!$C$62*J13) -> 350 | K37: =MAX(Inputs!$C$61,Inputs!$C$62*K13) -> 350 | ... Q37: =MAX(Inputs!$C$61,Inputs!$C$62*Q13) -> 350
A38: less: capital expenditures | D38: =-MAX(Inputs!$C$63,Inputs!$C$64*D13) -> -250 | E38: =-MAX(Inputs!$C$63,Inputs!$C$64*E13) -> -250 | F38: =-MAX(Inputs!$C$63,Inputs!$C$64*F13) -> -250 | G38: =-MAX(Inputs!$C$63,Inputs!$C$64*G13) -> -250 | H38: =-MAX(Inputs!$C$63,Inputs!$C$64*H13) -> -250 | I38: =-MAX(Inputs!$C$63,Inputs!$C$64*I13) -> -268.69339 | J38: =-MAX(Inputs!$C$63,Inputs!$C$64*J13) -> -312.53945 | K38: =-MAX(Inputs!$C$63,Inputs!$C$64*K13) -> -335.55853 | ... Q38: =-MAX(Inputs!$C$63,Inputs!$C$64*Q13) -> -371.41715
A39: less: increase in net working capital | D39: =-Inputs!$C$65*(D13-C13) -> -25.19424 | E39: =-Inputs!$C$65*(E13-D13) -> -117.20978 | F39: =-Inputs!$C$65*(F13-E13) -> -119.38656 | G39: =-Inputs!$C$65*(G13-F13) -> -201.11249 | H39: =-Inputs!$C$65*(H13-G13) -> -186.51324 | I39: =-Inputs!$C$65*(I13-H13) -> -187.19877 | J39: =-Inputs!$C$65*(J13-I13) -> -187.91172 | K39: =-Inputs!$C$65*(K13-J13) -> -98.653192 | ... Q39: =-Inputs!$C$65*(Q13-P13) -> -11.285055
A40: Unlevered free cash flow | D40: =SUM(D35:D39) -> -1852.3495 | E40: =SUM(E35:E39) -> -1312.1709 | F40: =SUM(F35:F39) -> -720.10864 | G40: =SUM(G35:G39) -> 189.65772 | H40: =SUM(H35:H39) -> 1086.7098 | I40: =SUM(I35:I39) -> 1932.2869 | J40: =SUM(J35:J39) -> 2631.9707 | K40: =SUM(K35:K39) -> 3082.8388 | ... Q40: =SUM(Q35:Q39) -> 3049.7331
A42: Discounting (mid-year convention, from valuation date)
A43: Discount period (years) | D43: =(DATE(D$4,6,30)-Inputs!$C$9)/365 -> 0.73424658 | E43: =(DATE(E$4,6,30)-Inputs!$C$9)/365 -> 1.7369863 | F43: =(DATE(F$4,6,30)-Inputs!$C$9)/365 -> 2.7369863 | G43: =(DATE(G$4,6,30)-Inputs!$C$9)/365 -> 3.7369863 | H43: =(DATE(H$4,6,30)-Inputs!$C$9)/365 -> 4.7369863 | I43: =(DATE(I$4,6,30)-Inputs!$C$9)/365 -> 5.739726 | J43: =(DATE(J$4,6,30)-Inputs!$C$9)/365 -> 6.739726 | K43: =(DATE(K$4,6,30)-Inputs!$C$9)/365 -> 7.739726 | ... Q43: =(DATE(Q$4,6,30)-Inputs!$C$9)/365 -> 13.745205
A44: Discount factor | D44: =1/(1+Inputs!$C$28)^D43 -> 0.9217094 | E44: =1/(1+Inputs!$C$28)^E43 -> 0.8245957 | F44: =1/(1+Inputs!$C$28)^F43 -> 0.7379386 | G44: =1/(1+Inputs!$C$28)^G43 -> 0.66038833 | H44: =1/(1+Inputs!$C$28)^H43 -> 0.59098785 | I44: =1/(1+Inputs!$C$28)^I43 -> 0.52871983 | J44: =1/(1+Inputs!$C$28)^J43 -> 0.47315645 | K44: =1/(1+Inputs!$C$28)^K43 -> 0.42343224 | ... Q44: =1/(1+Inputs!$C$28)^Q43 -> 0.21736753
A45: PV of free cash flow | D45: =D40*D44 -> -1707.328 | E45: =E40*E44 -> -1082.0105 | F45: =F40*F44 -> -531.39596 | G45: =G40*G44 -> 125.24774 | H45: =H40*H44 -> 642.23227 | I45: =I40*I44 -> 1021.6384 | J45: =J40*J44 -> 1245.3339 | K45: =K40*K44 -> 1305.3733 | ... Q45: =Q40*Q44 -> 662.91296

Sheet Sources
A1: Sources and notes
A3: Moderna Q4/FY2025 press release (8-K Ex. 99.1, Feb 13 2026): https://www.sec.gov/Archives/edgar/data/1682852/000168285226000015/exhibit9912025q4pressrelea.htm
A4: Moderna Q2 2026 press release (8-K Ex. 99.1, Jul 31 2026): https://www.sec.gov/Archives/edgar/data/0001682852/000168285226000147/exhibit9912026q2pressrelea.htm
A5: Moderna JPM 2026 update (8-K Ex. 99.1, Jan 12 2026): https://www.sec.gov/Archives/edgar/data/1682852/000168285226000007/exhibit991-01122026.htm
A6: Closing price Oct 2 2026 and market cap US$75.4bn: https://www.ad-hoc-news.de/boerse/news/corporate-news/moderna-stock-gained-0-57-percent-as-nasdaq-100-entry-nears/70226496
A7: 10-yr Treasury par yield 5.28% (Oct 2 2026): https://stockmarketwatch.com/bonds/10-year-treasury-yield
A8: William Blair (Aug 2026) 2040 intismeran sales to Moderna after 50/50 Merck profit share: melanoma >$5.4bn, NSCLC ~$10bn, RCC ~$3.3bn: https://www.benzinga.com/analyst-stock-ratings/upgrades/26/08/61333408/modernas-intismeran-close-to-keytruda-style-oncology-opportunity-analyst
A10: Method notes:
A11: - Valued on unlevered FCF for 2027-2040; 2026 is shown for reference only because its remaining cash burn is already reflected in the YE2026 cash guidance used in the equity bridge.
A12: - Intismeran revenue = Moderna's share under the 50/50 Merck collaboration, ramped linearly to peak and multiplied by probability of approval (risk-adjusted).
A13: - Stock-based compensation is treated as a real cost (left inside opex, not added back).
A14: - Interest income on cash is excluded from FCF; cash enters through the equity bridge.
A15: - Not investment advice. All forecasts and probabilities are illustrative assumptions.
